Workbook

Sheet Folha
C1: 45658 | D1: 45689 | E1: 45717 | F1: 45748 | G1: 45778 | H1: 45809 | I1: 45839 | J1: 45870 | K1: 45901 | L1: 45931 | M1: 45962 | N1: 45992
A2: Monike Bobroski Nunes
B3: Salário
B4: Alimentação
B5: Transporte
B6: Variável
B7: Férias
B8: 13º Salário
B9: Adiantamentos
C10: =SUM(C2:C9) -> 0 | D10: =SUM(D2:D9) -> 0 | E10: =SUM(E2:E9) -> 0 | F10: =SUM(F2:F9) -> 0 | G10: =SUM(G2:G9) -> 0 | H10: =SUM(H2:H9) -> 0 | I10: =SUM(I2:I9) -> 0 | J10: =SUM(J2:J9) -> 0 | ... N10: =SUM(N2:N9) -> 0
A11: Gabrielle Andrade
B12: Salário | C12: 1647.26 | E12: 1647.26
B13: Comissão | E13: 150
B14: Alimentação | C14: 374 | E14: 484
B15: Transporte | C15: 400 | E15: =551.2+10.8 -> 562
B16: Férias
B17: 13º Salário
B18: Multa/Descontos
B19: Adiantamentos
C20: =SUM(C11:C19) -> 2421.26 | D20: =SUM(D11:D19) -> 0 | E20: =SUM(E11:E19) -> 2843.26 | F20: =SUM(F11:F19) -> 0 | G20: =SUM(G11:G19) -> 0 | H20: =SUM(H11:H19) -> 0 | I20: =SUM(I11:I19) -> 0 | J20: =SUM(J11:J19) -> 0 | ... N20: =SUM(N11:N19) -> 0
A21: Pamela de Araujo Barroso
B22: Salário
B23: Alimentação
B24: Transporte
B25: Férias
B26: 13º Salário
B27: Multa/Descontos
B28: Adiantamentos
C29: =SUM(C21:C28) -> 0 | D29: =SUM(D21:D28) -> 0 | E29: =SUM(E21:E28) -> 0 | F29: =SUM(F21:F28) -> 0 | G29: =SUM(G21:G28) -> 0 | H29: =SUM(H21:H28) -> 0 | I29: =SUM(I21:I28) -> 0 | J29: =SUM(J21:J28) -> 0 | ... N29: =SUM(N21:N28) -> 0
A30: Tamires Caroline Borges Bento Leal
B31: Salário | C31: 604.89 | D31: 951.17 | E31: 3391.46
B32: Comissão | C32: 150
B33: Alimentação | C33: 374
B34: Transporte | C34: =207.2+592 -> 799.2
B35: Férias
B36: 13º Salário
B37: Multa/Descontos
B38: Adiantamentos
C39: =SUM(C30:C38) -> 1928.09 | D39: =SUM(D30:D38) -> 951.17 | E39: =SUM(E30:E38) -> 3391.46 | F39: =SUM(F30:F38) -> 0 | G39: =SUM(G30:G38) -> 0 | H39: =SUM(H30:H38) -> 0 | I39: =SUM(I30:I38) -> 0 | J39: =SUM(J30:J38) -> 0 | ... N39: =SUM(N30:N38) -> 0
A40: Edurado Mancan
...

Sheet FATURAMENTO 
B1: 46023 | E1: 46054 | H1: 46082 | K1: 46113 | N1: 46143 | Q1: 46174 | T1: 46204 | W1: 46235 | Z1: 46266 | AC1: 46296 | AF1: 46327 | AI1: 46357
A2: RECEITAS
A4: CAIXA
A6: Goethe Imóveis Pipeimobi | B6: 4006.34
A7: Goethe Imóveis Pipeimobi | B7: 3346.4
A8: Ato do contrato 189591 - Praia e Belas 1762 106 - Cleiton - Repassado no mesmo dia | B8: 20000
A9: Goethe Imóveis Pipeimobi | E9: 3000
A10: Goethe Imóveis Pipeimobi | E10: 2539.21
A11: Goethe Imóveis Pipeimobi | E11: 5000
A12: Goethe Imóveis Pipeimobi | H12: 2741.06
A13: Crédito não identificado ??????? | H13: 492.9
A14: Crédito não identificado ??????? | H14: 990
A15: Crédito não identificado ??????? | H15: 4200
A16: Crédito não identificado ??????? | H16: 1050
A17: Crédito não identificado ??????? | H17: 1470
A24: PIPEIMOB
A26: Antecipação de Comissão - Contrato 448520 - Ferreira Viana, 885, 512 | B26: 1550
A27: Antecipação de Comissão - Contrato 299409 (CT 12564) - Doutor Otávio Santos, 257, 507 | B27: 1130
A28: Antecipação de Comissão - Contrato 719417 - Reverendo Olavo Nunes, 280, 502 | B28: 2100
A29: Antecipação de Comissão - Contrato 308794 - HIPOLITO DA COSTA, 211, 301 | B29: 1510
A30: Crédito do Pipeimob ??????? | B30: 4720
A31: Contrato 147120 - INDEPENDENCIA, 519, 203 - Rosemeri | B31: 9450
A32: Contrato 876859 (CT 12176) - Gabriel Franco da Luz 175, 308 | B32: 2760
A33: Contrato 272703 - GETULIO VARGAS, 1151, 516 | B33: 693.6
A34: Contrato 474600 - Engenheiro Ludolfo Boehl, 931, 13 | B34: 910
A35: Contrato 368073 - DOUTOR POSSIDONIO CUNHA, 719, 2 Parte 1 de 2 | B35: 2414
A36: Contrato 368073 - DOUTOR POSSIDONIO CUNHA, 719, 2 Parte 2 de 2 | B36: 4828
A37: Contrato 448520 - Ferreira Viana, 885, 512 | B37: 1212.46
... A45: Antecipação de Comissão - Contrato 474600 - Engenheiro Ludolfo Boehl, 931, 13 | B45: 3180
A46: Contrato 401279 - JOAO PESSOA, 105, 501, Farroupilha, Porto Alegre - RS, CEP 90040-001 | E46: 413.1
A47: Contrato 415673 - ALMIRANTE ABREU, 354, 801, Rio Branco, Porto Alegre / RS, CEP 90420010 | E47: 13125
A48: Contrato 448520 - Ferreira Viana, 885, 512, Petrópolis, Porto Alegre / RS, CEP 90670-100 | E48: 1896.42
A49: Contrato 474600 - Engenheiro Ludolfo Boehl, 931, 13, Teresópolis, Porto Alegre / RS, CEP 91720150 | E49: 910
A50: Contrato 495832 - Dona Otília, 3804, 401, Santa Tereza, Porto Alegre / RS, CEP 90830580 | E50: 4200
A51: Contrato 748245 - Soledade, 371, 602, Petrópolis, Porto Alegre / RS, CEP 90470-340 | E51: 8925
A52: Contrato 759002 - da Azenha, 1338, 31, Azenha, Porto Alegre / RS, CEP 90160-003 | E52: 4200
A53: Contrato 759847 - Independência, 972, 607, Independência, Porto Alegre / RS, CEP 90035072 | E53: 20592
A54: Devolução de Antecipação de Comissão - 448520 - Ferreira Viana, 885, 512, Petrópolis, Porto Alegre / RS, CEP 90670-100 | E54: -1683.19
A55: Devolução de Antecipação de Comissão - 722551 - GENERAL JOAO TELLES, 68, 502, Bom Fim, Porto Alegre / RS, CEP 90035-120 | E55: -3446.79
A56: Devolução de Antecipação de Comissão - 750147 - Jari, 735, 909, Passo da Areia, Porto Alegre / RS, CEP 91350170 | E56: -6379.45
...

Sheet DESPESAS
B1: 46023 | F1: 46054 | J1: 46082 | N1: 46113 | R1: 46143 | V1: 46174 | Z1: 46204 | AD1: 46235 | AH1: 46266 | AL1: 46296 | AP1: 46327 | AT1: 46357 | AX1: ACUMULADO 2026 | BB1: Rateio de Venda: | BC1: 100
B2: TOTAL | C2: VENDA | D2: ALUGUEL | E2: REFERÊNCIA | F2: TOTAL | G2: VENDA | H2: ALUGUEL | I2: REFERÊNCIA | J2: TOTAL | K2: VENDA | L2: ALUGUEL | M2: REFERÊNCIA | N2: TOTAL | O2: VENDA | P2: ALUGUEL | Q2: REFERÊNCIA | R2: TOTAL | S2: VENDA | T2: ALUGUEL | U2: REFERÊNCIA | V2: TOTAL | W2: VENDA | X2: ALUGUEL | Y2: REFERÊNCIA | Z2: TOTAL | AA2: VENDA | AB2: ALUGUEL | AC2: REFERÊNCIA | AD2: TOTAL | AE2: VENDA | AF2: ALUGUEL | AG2: REFERÊNCIA | AH2: TOTAL | AI2: VENDA | AJ2: ALUGUEL | AK2: REFERÊNCIA | AL2: TOTAL | AM2: VENDA | AN2: ALUGUEL | AO2: REFERÊNCIA | AP2: TOTAL | AQ2: VENDA | AR2: ALUGUEL | AS2: REFERÊNCIA | AT2: TOTAL | AU2: VENDA | AV2: ALUGUEL | AW2: REFERÊNCIA | AX2: TOTAL | AY2: VENDA | AZ2: ALUGUEL | BA2: VENDA | BB2: ALUGUEL | BC2: Valor do Rateio
A3: CONTAS DE CONSUMO
A4: GASTOS ESPAÇO FÍSICO
A5: Água Mineral | B5: =C5+D5 -> 0 | C5: =E5*$BA5/100 -> 0 | D5: =E5*$BB5/100 -> 0 | F5: =G5+H5 -> 0 | G5: =I5*$BA5/100 -> 0 | H5: =I5*$BB5/100 -> 0 | J5: =K5+L5 -> 0 | K5: =M5*$BA5/100 -> 0 | L5: =M5*$BB5/100 -> 0 | N5: =O5+P5 -> 0 | O5: =Q5*$BA5/100 -> 0 | P5: =Q5*$BB5/100 -> 0 | R5: =S5+T5 -> 0 | S5: =U5*$BA5/100 -> 0 | T5: =U5*$BB5/100 -> 0 | V5: =W5+X5 -> 0 | W5: =Y5*$BA5/100 -> 0 | X5: =Y5*$BB5/100 -> 0 | Z5: =AA5+AB5 -> 0 | AA5: =AC5*$BA5/100 -> 0 | AB5: =AC5*$BB5/100 -> 0 | AD5: =AE5+AF5 -> 0 | AE5: =AG5*$BA5/100 -> 0 | AF5: =AG5*$BB5/100 -> 0 | AH5: =AI5+AJ5 -> 0 | AI5: =AK5*$BA5/100 -> 0 | AJ5: =AK5*$BB5/100 -> 0 | AL5: =AM5+AN5 -> 0 | AM5: =AO5*$BA5/100 -> 0 | AN5: =AO5*$BB5/100 -> 0 | AP5: =AQ5+AR5 -> 0 | AQ5: =AS5*$BA5/100 -> 0 | AR5: =AS5*$BB5/100 -> 0 | AT5: =AU5+AV5 -> 0 | AU5: =AW5*$BA5/100 -> 0 | AV5: =AW5*$BB5/100 -> 0 | AX5: =B5+F5+J5+N5+R5+V5+Z5+AD5+AH5+AL5+AP5+AT5 -> 0 | AY5: =C5+G5+K5+O5+S5+W5+AA5+AE5+AI5+AM5+AQ5+AU5 -> 0 | AZ5: =D5+H5+L5+P5+T5+X5+AB5+AF5+AJ5+AN5+AR5+AV5 -> 0 | BA5: =BC$1 -> 100 | BB5: =100-BA5 -> 0 | BC5: =AX5*(BB5/100) -> 0 | BF5: CELULARES
A6: Aluguel /IPTU | B6: =C6+D6 -> 16946.5 | C6: =E6*$BA6/100 -> 16946.5 | D6: =E6*$BB6/100 -> 0 | E6: 16946.5 | F6: =G6+H6 -> 16715.19 | G6: =I6*$BA6/100 -> 16715.19 | H6: =I6*$BB6/100 -> 0 | I6: 16715.19 | J6: =K6+L6 -> 0 | K6: =M6*$BA6/100 -> 0 | L6: =M6*$BB6/100 -> 0 | N6: =O6+P6 -> 0 | O6: =Q6*$BA6/100 -> 0 | P6: =Q6*$BB6/100 -> 0 | R6: =S6+T6 -> 0 | S6: =U6*$BA6/100 -> 0 | T6: =U6*$BB6/100 -> 0 | V6: =W6+X6 -> 0 | W6: =Y6*$BA6/100 -> 0 | X6: =Y6*$BB6/100 -> 0 | Z6: =AA6+AB6 -> 0 | AA6: =AC6*$BA6/100 -> 0 | AB6: =AC6*$BB6/100 -> 0 | AD6: =AE6+AF6 -> 0 | AE6: =AG6*$BA6/100 -> 0 | AF6: =AG6*$BB6/100 -> 0 | AH6: =AI6+AJ6 -> 0 | AI6: =AK6*$BA6/100 -> 0 | AJ6: =AK6*$BB6/100 -> 0 | AL6: =AM6+AN6 -> 0 | AM6: =AO6*$BA6/100 -> 0 | AN6: =AO6*$BB6/100 -> 0 | AP6: =AQ6+AR6 -> 0 | AQ6: =AS6*$BA6/100 -> 0 | AR6: =AS6*$BB6/100 -> 0 | AT6: =AU6+AV6 -> 0 | AU6: =AW6*$BA6/100 -> 0 | AV6: =AW6*$BB6/100 -> 0 | AX6: =B6+F6+J6+N6+R6+V6+Z6+AD6+AH6+AL6+AP6+AT6 -> 33661.69 | AY6: =C6+G6+K6+O6+S6+W6+AA6+AE6+AI6+AM6+AQ6+AU6 -> 33661.69 | AZ6: =D6+H6+L6+P6+T6+X6+AB6+AF6+AJ6+AN6+AR6+AV6 -> 0 | BA6: =BC$1 -> 100 | BB6: =100-BA6 -> 0 | BC6: =AX6*(BB6/100) -> 0 | BF6: 1 | BG6: andressa
A7: Claro - celular | B7: =C7+D7 -> 293.38 | C7: =E7*$BA7/100 -> 0 | D7: =E7*$BB7/100 -> 293.38 | E7: 293.38 | F7: =G7+H7 -> 300.5 | G7: =I7*$BA7/100 -> 0 | H7: =I7*$BB7/100 -> 300.5 | I7: 300.5 | J7: =K7+L7 -> 392.24 | K7: =M7*$BA7/100 -> 0 | L7: =M7*$BB7/100 -> 392.24 | M7: 392.24 | N7: =O7+P7 -> 0 | O7: =Q7*$BA7/100 -> 0 | P7: =Q7*$BB7/100 -> 0 | R7: =S7+T7 -> 0 | S7: =U7*$BA7/100 -> 0 | T7: =U7*$BB7/100 -> 0 | V7: =W7+X7 -> 0 | W7: =Y7*$BA7/100 -> 0 | X7: =Y7*$BB7/100 -> 0 | Z7: =AA7+AB7 -> 0 | AA7: =AC7*$BA7/100 -> 0 | AB7: =AC7*$BB7/100 -> 0 | AD7: =AE7+AF7 -> 0 | AE7: =AG7*$BA7/100 -> 0 | AF7: =AG7*$BB7/100 -> 0 | AH7: =AI7+AJ7 -> 0 | AI7: =AK7*$BA7/100 -> 0 | AJ7: =AK7*$BB7/100 -> 0 | AL7: =AM7+AN7 -> 0 | AM7: =AO7*$BA7/100 -> 0 | AN7: =AO7*$BB7/100 -> 0 | AP7: =AQ7+AR7 -> 0 | AQ7: =AS7*$BA7/100 -> 0 | AR7: =AS7*$BB7/100 -> 0 | AT7: =AU7+AV7 -> 0 | AU7: =AW7*$BA7/100 -> 0 | AV7: =AW7*$BB7/100 -> 0 | AX7: =B7+F7+J7+N7+R7+V7+Z7+AD7+AH7+AL7+AP7+AT7 -> 986.12 | AY7: =C7+G7+K7+O7+S7+W7+AA7+AE7+AI7+AM7+AQ7+AU7 -> 0 | AZ7: =D7+H7+L7+P7+T7+X7+AB7+AF7+AJ7+AN7+AR7+AV7 -> 986.12 | BA7: 0 | BB7: =100-BA7 -> 100 | BF7: 1 | BG7: douglas
A8: Contabilidade | B8: =C8+D8 -> 350 | C8: =E8*$BA8/100 -> 350 | D8: =E8*$BB8/100 -> 0 | E8: 350 | F8: =G8+H8 -> 350 | G8: =I8*$BA8/100 -> 350 | H8: =I8*$BB8/100 -> 0 | I8: 350 | J8: =K8+L8 -> 0 | K8: =M8*$BA8/100 -> 0 | L8: =M8*$BB8/100 -> 0 | N8: =O8+P8 -> 0 | O8: =Q8*$BA8/100 -> 0 | P8: =Q8*$BB8/100 -> 0 | R8: =S8+T8 -> 0 | S8: =U8*$BA8/100 -> 0 | T8: =U8*$BB8/100 -> 0 | V8: =W8+X8 -> 0 | W8: =Y8*$BA8/100 -> 0 | X8: =Y8*$BB8/100 -> 0 | Z8: =AA8+AB8 -> 0 | AA8: =AC8*$BA8/100 -> 0 | AB8: =AC8*$BB8/100 -> 0 | AD8: =AE8+AF8 -> 0 | AE8: =AG8*$BA8/100 -> 0 | AF8: =AG8*$BB8/100 -> 0 | AH8: =AI8+AJ8 -> 0 | AI8: =AK8*$BA8/100 -> 0 | AJ8: =AK8*$BB8/100 -> 0 | AL8: =AM8+AN8 -> 0 | AM8: =AO8*$BA8/100 -> 0 | AN8: =AO8*$BB8/100 -> 0 | AP8: =AQ8+AR8 -> 0 | AQ8: =AS8*$BA8/100 -> 0 | AR8: =AS8*$BB8/100 -> 0 | AT8: =AU8+AV8 -> 0 | AU8: =AW8*$BA8/100 -> 0 | AV8: =AW8*$BB8/100 -> 0 | AX8: =B8+F8+J8+N8+R8+V8+Z8+AD8+AH8+AL8+AP8+AT8 -> 700 | AY8: =C8+G8+K8+O8+S8+W8+AA8+AE8+AI8+AM8+AQ8+AU8 -> 700 | AZ8: =D8+H8+L8+P8+T8+X8+AB8+AF8+AJ8+AN8+AR8+AV8 -> 0 | BA8: =BC$1 -> 100 | BB8: =100-BA8 -> 0 | BC8: =AX8*(BB8/100) -> 0 | BF8: 1 | BG8: recepção
A9: Extintores | B9: =C9+D9 -> 0 | C9: =E9*$BA9/100 -> 0 | D9: =E9*$BB9/100 -> 0 | F9: =G9+H9 -> 0 | G9: =I9*$BA9/100 -> 0 | H9: =I9*$BB9/100 -> 0 | J9: =K9+L9 -> 0 | K9: =M9*$BA9/100 -> 0 | L9: =M9*$BB9/100 -> 0 | N9: =O9+P9 -> 0 | O9: =Q9*$BA9/100 -> 0 | P9: =Q9*$BB9/100 -> 0 | R9: =S9+T9 -> 0 | S9: =U9*$BA9/100 -> 0 | T9: =U9*$BB9/100 -> 0 | V9: =W9+X9 -> 0 | W9: =Y9*$BA9/100 -> 0 | X9: =Y9*$BB9/100 -> 0 | Z9: =AA9+AB9 -> 0 | AA9: =AC9*$BA9/100 -> 0 | AB9: =AC9*$BB9/100 -> 0 | AD9: =AE9+AF9 -> 0 | AE9: =AG9*$BA9/100 -> 0 | AF9: =AG9*$BB9/100 -> 0 | AH9: =AI9+AJ9 -> 0 | AI9: =AK9*$BA9/100 -> 0 | AJ9: =AK9*$BB9/100 -> 0 | AL9: =AM9+AN9 -> 0 | AM9: =AO9*$BA9/100 -> 0 | AN9: =AO9*$BB9/100 -> 0 | AP9: =AQ9+AR9 -> 0 | AQ9: =AS9*$BA9/100 -> 0 | AR9: =AS9*$BB9/100 -> 0 | AT9: =AU9+AV9 -> 0 | AU9: =AW9*$BA9/100 -> 0 | AV9: =AW9*$BB9/100 -> 0 | AX9: =B9+F9+J9+N9+R9+V9+Z9+AD9+AH9+AL9+AP9+AT9 -> 0 | AY9: =C9+G9+K9+O9+S9+W9+AA9+AE9+AI9+AM9+AQ9+AU9 -> 0 | AZ9: =D9+H9+L9+P9+T9+X9+AB9+AF9+AJ9+AN9+AR9+AV9 -> 0 | BA9: =BC$1 -> 100 | BB9: =100-BA9 -> 0 | BC9: =AX9*(BB9/100) -> 0 | BF9: 1 | BG9: jonas
A10: Informática | B10: =C10+D10 -> 0 | C10: =E10*$BA10/100 -> 0 | D10: =E10*$BB10/100 -> 0 | F10: =G10+H10 -> 270 | G10: =I10*$BA10/100 -> 270 | H10: =I10*$BB10/100 -> 0 | I10: 270 | J10: =K10+L10 -> 0 | K10: =M10*$BA10/100 -> 0 | L10: =M10*$BB10/100 -> 0 | N10: =O10+P10 -> 0 | O10: =Q10*$BA10/100 -> 0 | P10: =Q10*$BB10/100 -> 0 | R10: =S10+T10 -> 0 | S10: =U10*$BA10/100 -> 0 | T10: =U10*$BB10/100 -> 0 | V10: =W10+X10 -> 0 | W10: =Y10*$BA10/100 -> 0 | X10: =Y10*$BB10/100 -> 0 | Z10: =AA10+AB10 -> 0 | AA10: =AC10*$BA10/100 -> 0 | AB10: =AC10*$BB10/100 -> 0 | AD10: =AE10+AF10 -> 0 | AE10: =AG10*$BA10/100 -> 0 | AF10: =AG10*$BB10/100 -> 0 | AH10: =AI10+AJ10 -> 0 | AI10: =AK10*$BA10/100 -> 0 | AJ10: =AK10*$BB10/100 -> 0 | AL10: =AM10+AN10 -> 0 | AM10: =AO10*$BA10/100 -> 0 | AN10: =AO10*$BB10/100 -> 0 | AP10: =AQ10+AR10 -> 0 | AQ10: =AS10*$BA10/100 -> 0 | AR10: =AS10*$BB10/100 -> 0 | AT10: =AU10+AV10 -> 0 | AU10: =AW10*$BA10/100 -> 0 | AV10: =AW10*$BB10/100 -> 0 | AX10: =B10+F10+J10+N10+R10+V10+Z10+AD10+AH10+AL10+AP10+AT10 -> 270 | AY10: =C10+G10+K10+O10+S10+W10+AA10+AE10+AI10+AM10+AQ10+AU10 -> 270 | AZ10: =D10+H10+L10+P10+T10+X10+AB10+AF10+AJ10+AN10+AR10+AV10 -> 0 | BA10: =BC$1 -> 100 | BB10: =100-BA10 -> 0 | BC10: =AX10*(BB10/100) -> 0
A11: Limpeza da Loja | B11: =C11+D11 -> 1350 | C11: =E11*$BA11/100 -> 1350 | D11: =E11*$BB11/100 -> 0 | E11: =450+450+450 -> 1350 | F11: =G11+H11 -> 1350 | G11: =I11*$BA11/100 -> 1350 | H11: =I11*$BB11/100 -> 0 | I11: =450+300+150+450 -> 1350 | J11: =K11+L11 -> 1200 | K11: =M11*$BA11/100 -> 1200 | L11: =M11*$BB11/100 -> 0 | M11: =450+300+450 -> 1200 | N11: =O11+P11 -> 0 | O11: =Q11*$BA11/100 -> 0 | P11: =Q11*$BB11/100 -> 0 | R11: =S11+T11 -> 0 | S11: =U11*$BA11/100 -> 0 | T11: =U11*$BB11/100 -> 0 | V11: =W11+X11 -> 0 | W11: =Y11*$BA11/100 -> 0 | X11: =Y11*$BB11/100 -> 0 | Z11: =AA11+AB11 -> 0 | AA11: =AC11*$BA11/100 -> 0 | AB11: =AC11*$BB11/100 -> 0 | AD11: =AE11+AF11 -> 0 | AE11: =AG11*$BA11/100 -> 0 | AF11: =AG11*$BB11/100 -> 0 | AH11: =AI11+AJ11 -> 0 | AI11: =AK11*$BA11/100 -> 0 | AJ11: =AK11*$BB11/100 -> 0 | AL11: =AM11+AN11 -> 0 | AM11: =AO11*$BA11/100 -> 0 | AN11: =AO11*$BB11/100 -> 0 | AP11: =AQ11+AR11 -> 0 | AQ11: =AS11*$BA11/100 -> 0 | AR11: =AS11*$BB11/100 -> 0 | AT11: =AU11+AV11 -> 0 | AU11: =AW11*$BA11/100 -> 0 | AV11: =AW11*$BB11/100 -> 0 | AX11: =B11+F11+J11+N11+R11+V11+Z11+AD11+AH11+AL11+AP11+AT11 -> 3900 | AY11: =C11+G11+K11+O11+S11+W11+AA11+AE11+AI11+AM11+AQ11+AU11 -> 3900 | AZ11: =D11+H11+L11+P11+T11+X11+AB11+AF11+AJ11+AN11+AR11+AV11 -> 0 | BA11: =BC$1 -> 100 | BB11: =100-BA11 -> 0 | BC11: =AX11*(BB11/100) -> 0
A12: Algar - telefone fixo e internet | B12: =C12+D12 -> 0 | C12: =E12*$BA12/100 -> 0 | D12: =E12*$BB12/100 -> 0 | F12: =G12+H12 -> 203.43 | G12: =I12*$BA12/100 -> 203.43 | H12: =I12*$BB12/100 -> 0 | I12: 203.43 | J12: =K12+L12 -> 205.39 | K12: =M12*$BA12/100 -> 205.39 | L12: =M12*$BB12/100 -> 0 | M12: 205.39 | N12: =O12+P12 -> 0 | O12: =Q12*$BA12/100 -> 0 | P12: =Q12*$BB12/100 -> 0 | R12: =S12+T12 -> 0 | S12: =U12*$BA12/100 -> 0 | T12: =U12*$BB12/100 -> 0 | V12: =W12+X12 -> 0 | W12: =Y12*$BA12/100 -> 0 | X12: =Y12*$BB12/100 -> 0 | Z12: =AA12+AB12 -> 0 | AA12: =AC12*$BA12/100 -> 0 | AB12: =AC12*$BB12/100 -> 0 | AD12: =AE12+AF12 -> 0 | AE12: =AG12*$BA12/100 -> 0 | AF12: =AG12*$BB12/100 -> 0 | AH12: =AI12+AJ12 -> 0 | AI12: =AK12*$BA12/100 -> 0 | AJ12: =AK12*$BB12/100 -> 0 | AL12: =AM12+AN12 -> 0 | AM12: =AO12*$BA12/100 -> 0 | AN12: =AO12*$BB12/100 -> 0 | AP12: =AQ12+AR12 -> 0 | AQ12: =AS12*$BA12/100 -> 0 | AR12: =AS12*$BB12/100 -> 0 | AT12: =AU12+AV12 -> 0 | AU12: =AW12*$BA12/100 -> 0 | AV12: =AW12*$BB12/100 -> 0 | AX12: =B12+F12+J12+N12+R12+V12+Z12+AD12+AH12+AL12+AP12+AT12 -> 408.82 | AY12: =C12+G12+K12+O12+S12+W12+AA12+AE12+AI12+AM12+AQ12+AU12 -> 408.82 | AZ12: =D12+H12+L12+P12+T12+X12+AB12+AF12+AJ12+AN12+AR12+AV12 -> 0 | BA12: =BC$1 -> 100 | BB12: =100-BA12 -> 0 | BC12: =AX12*(BB12/100) -> 0
A13: ENERGIA | B13: =C13+D13 -> 1134.25 | C13: =E13*$BA13/100 -> 1134.25 | D13: =E13*$BB13/100 -> 0 | E13: 1134.25 | F13: =G13+H13 -> 0 | G13: =I13*$BA13/100 -> 0 | H13: =I13*$BB13/100 -> 0 | J13: =K13+L13 -> 1171.98 | K13: =M13*$BA13/100 -> 1171.98 | L13: =M13*$BB13/100 -> 0 | M13: 1171.98 | N13: =O13+P13 -> 0 | O13: =Q13*$BA13/100 -> 0 | P13: =Q13*$BB13/100 -> 0 | R13: =S13+T13 -> 0 | S13: =U13*$BA13/100 -> 0 | T13: =U13*$BB13/100 -> 0 | V13: =W13+X13 -> 0 | W13: =Y13*$BA13/100 -> 0 | X13: =Y13*$BB13/100 -> 0 | Z13: =AA13+AB13 -> 0 | AA13: =AC13*$BA13/100 -> 0 | AB13: =AC13*$BB13/100 -> 0 | AD13: =AE13+AF13 -> 0 | AE13: =AG13*$BA13/100 -> 0 | AF13: =AG13*$BB13/100 -> 0 | AH13: =AI13+AJ13 -> 0 | AI13: =AK13*$BA13/100 -> 0 | AJ13: =AK13*$BB13/100 -> 0 | AL13: =AM13+AN13 -> 0 | AM13: =AO13*$BA13/100 -> 0 | AN13: =AO13*$BB13/100 -> 0 | AP13: =AQ13+AR13 -> 0 | AQ13: =AS13*$BA13/100 -> 0 | AR13: =AS13*$BB13/100 -> 0 | AT13: =AU13+AV13 -> 0 | AU13: =AW13*$BA13/100 -> 0 | AV13: =AW13*$BB13/100 -> 0 | AX13: =B13+F13+J13+N13+R13+V13+Z13+AD13+AH13+AL13+AP13+AT13 -> 2306.23 | AY13: =C13+G13+K13+O13+S13+W13+AA13+AE13+AI13+AM13+AQ13+AU13 -> 2306.23 | AZ13: =D13+H13+L13+P13+T13+X13+AB13+AF13+AJ13+AN13+AR13+AV13 -> 0 | BA13: =BC$1 -> 100 | BB13: =100-BA13 -> 0 | BC13: =AX13*(BB13/100) -> 0
A14: Segurança SP | B14: =C14+D14 -> 0 | C14: =E14*$BA14/100 -> 0 | D14: =E14*$BB14/100 -> 0 | F14: =G14+H14 -> 361.86 | G14: =I14*$BA14/100 -> 361.86 | H14: =I14*$BB14/100 -> 0 | I14: =176.39+185.47 -> 361.86 | J14: =K14+L14 -> 0 | K14: =M14*$BA14/100 -> 0 | L14: =M14*$BB14/100 -> 0 | N14: =O14+P14 -> 0 | O14: =Q14*$BA14/100 -> 0 | P14: =Q14*$BB14/100 -> 0 | R14: =S14+T14 -> 0 | S14: =U14*$BA14/100 -> 0 | T14: =U14*$BB14/100 -> 0 | V14: =W14+X14 -> 0 | W14: =Y14*$BA14/100 -> 0 | X14: =Y14*$BB14/100 -> 0 | Z14: =AA14+AB14 -> 0 | AA14: =AC14*$BA14/100 -> 0 | AB14: =AC14*$BB14/100 -> 0 | AD14: =AE14+AF14 -> 0 | AE14: =AG14*$BA14/100 -> 0 | AF14: =AG14*$BB14/100 -> 0 | AH14: =AI14+AJ14 -> 0 | AI14: =AK14*$BA14/100 -> 0 | AJ14: =AK14*$BB14/100 -> 0 | AL14: =AM14+AN14 -> 0 | AM14: =AO14*$BA14/100 -> 0 | AN14: =AO14*$BB14/100 -> 0 | AP14: =AQ14+AR14 -> 0 | AQ14: =AS14*$BA14/100 -> 0 | AR14: =AS14*$BB14/100 -> 0 | AT14: =AU14+AV14 -> 0 | AU14: =AW14*$BA14/100 -> 0 | AV14: =AW14*$BB14/100 -> 0 | AX14: =B14+F14+J14+N14+R14+V14+Z14+AD14+AH14+AL14+AP14+AT14 -> 361.86 | AY14: =C14+G14+K14+O14+S14+W14+AA14+AE14+AI14+AM14+AQ14+AU14 -> 361.86 | AZ14: =D14+H14+L14+P14+T14+X14+AB14+AF14+AJ14+AN14+AR14+AV14 -> 0 | BA14: =BC$1 -> 100 | BB14: =100-BA14 -> 0 | BC14: =AX14*(BB14/100) -> 0
A15: TOTAL | B15: =SUM(B5:B14) -> 20074.13 | C15: =SUM(C5:C14) -> 19780.75 | D15: =SUM(D5:D14) -> 293.38 | E15: =SUM(E5:E14) -> 20074.13 | F15: =SUM(F5:F14) -> 19550.98 | G15: =SUM(G5:G14) -> 19250.48 | H15: =SUM(H5:H14) -> 300.5 | I15: =SUM(I5:I14) -> 19550.98 | ... AW15: =SUM(AW5:AW14) -> 0 | AX15: =B15+F15+J15+N15+R15+V15+Z15+AD15+AH15+AL15+AP15+AT15 -> 42594.72 | AY15: =C15+G15+K15+O15+S15+W15+AA15+AE15+AI15+AM15+AQ15+AU15 -> 41608.6 | AZ15: =D15+H15+L15+P15+T15+X15+AB15+AF15+AJ15+AN15+AR15+AV15 -> 986.12 | BC15: =SUM(BC4:BC14) -> 0
A16: MATERIAL
A17: Mantimentos | B17: =C17+D17 -> 0 | C17: =E17*$BA17/100 -> 0 | D17: =E17*$BB17/100 -> 0 | F17: =G17+H17 -> 0 | G17: =I17*$BA17/100 -> 0 | H17: =I17*$BB17/100 -> 0 | J17: =K17+L17 -> 905.03 | K17: =M17*$BA17/100 -> 905.03 | L17: =M17*$BB17/100 -> 0 | M17: 905.03 | N17: =O17+P17 -> 0 | O17: =Q17*$BA17/100 -> 0 | P17: =Q17*$BB17/100 -> 0 | R17: =S17+T17 -> 0 | S17: =U17*$BA17/100 -> 0 | T17: =U17*$BB17/100 -> 0 | V17: =W17+X17 -> 0 | W17: =Y17*$BA17/100 -> 0 | X17: =Y17*$BB17/100 -> 0 | Z17: =AA17+AB17 -> 0 | AA17: =AC17*$BA17/100 -> 0 | AB17: =AC17*$BB17/100 -> 0 | AD17: =AE17+AF17 -> 0 | AE17: =AG17*$BA17/100 -> 0 | AF17: =AG17*$BB17/100 -> 0 | AH17: =AI17+AJ17 -> 0 | AI17: =AK17*$BA17/100 -> 0 | AJ17: =AK17*$BB17/100 -> 0 | AL17: =AM17+AN17 -> 0 | AM17: =AO17*$BA17/100 -> 0 | AN17: =AO17*$BB17/100 -> 0 | AP17: =AQ17+AR17 -> 0 | AQ17: =AS17*$BA17/100 -> 0 | AR17: =AS17*$BB17/100 -> 0 | AT17: =AU17+AV17 -> 0 | AU17: =AW17*$BA17/100 -> 0 | AV17: =AW17*$BB17/100 -> 0 | AX17: =B17+F17+J17+N17+R17+V17+Z17+AD17+AH17+AL17+AP17+AT17 -> 905.03 | AY17: =C17+G17+K17+O17+S17+W17+AA17+AE17+AI17+AM17+AQ17+AU17 -> 905.03 | AZ17: =D17+H17+L17+P17+T17+X17+AB17+AF17+AJ17+AN17+AR17+AV17 -> 0 | BA17: =BC$1 -> 100 | BB17: =100-BA17 -> 0 | BC17: =AX17*(BB17/100) -> 0
A18: Material de limpeza | B18: =C18+D18 -> 0 | C18: =E18*$BA18/100 -> 0 | D18: =E18*$BB18/100 -> 0 | F18: =G18+H18 -> 0 | G18: =I18*$BA18/100 -> 0 | H18: =I18*$BB18/100 -> 0 | J18: =K18+L18 -> 0 | K18: =M18*$BA18/100 -> 0 | L18: =M18*$BB18/100 -> 0 | N18: =O18+P18 -> 0 | O18: =Q18*$BA18/100 -> 0 | P18: =Q18*$BB18/100 -> 0 | R18: =S18+T18 -> 0 | S18: =U18*$BA18/100 -> 0 | T18: =U18*$BB18/100 -> 0 | V18: =W18+X18 -> 0 | W18: =Y18*$BA18/100 -> 0 | X18: =Y18*$BB18/100 -> 0 | Z18: =AA18+AB18 -> 0 | AA18: =AC18*$BA18/100 -> 0 | AB18: =AC18*$BB18/100 -> 0 | AD18: =AE18+AF18 -> 0 | AE18: =AG18*$BA18/100 -> 0 | AF18: =AG18*$BB18/100 -> 0 | AH18: =AI18+AJ18 -> 0 | AI18: =AK18*$BA18/100 -> 0 | AJ18: =AK18*$BB18/100 -> 0 | AL18: =AM18+AN18 -> 0 | AM18: =AO18*$BA18/100 -> 0 | AN18: =AO18*$BB18/100 -> 0 | AP18: =AQ18+AR18 -> 0 | AQ18: =AS18*$BA18/100 -> 0 | AR18: =AS18*$BB18/100 -> 0 | AT18: =AU18+AV18 -> 0 | AU18: =AW18*$BA18/100 -> 0 | AV18: =AW18*$BB18/100 -> 0 | AX18: =B18+F18+J18+N18+R18+V18+Z18+AD18+AH18+AL18+AP18+AT18 -> 0 | AY18: =C18+G18+K18+O18+S18+W18+AA18+AE18+AI18+AM18+AQ18+AU18 -> 0 | AZ18: =D18+H18+L18+P18+T18+X18+AB18+AF18+AJ18+AN18+AR18+AV18 -> 0 | BA18: =BC$1 -> 100 | BB18: =100-BA18 -> 0 | BC18: =AX18*(BB18/100) -> 0
A19: Material de escritório | B19: =C19+D19 -> 200.7 | C19: =E19*$BA19/100 -> 200.7 | D19: =E19*$BB19/100 -> 0 | E19: 200.7 | F19: =G19+H19 -> 0 | G19: =I19*$BA19/100 -> 0 | H19: =I19*$BB19/100 -> 0 | J19: =K19+L19 -> 0 | K19: =M19*$BA19/100 -> 0 | L19: =M19*$BB19/100 -> 0 | N19: =O19+P19 -> 0 | O19: =Q19*$BA19/100 -> 0 | P19: =Q19*$BB19/100 -> 0 | R19: =S19+T19 -> 0 | S19: =U19*$BA19/100 -> 0 | T19: =U19*$BB19/100 -> 0 | V19: =W19+X19 -> 0 | W19: =Y19*$BA19/100 -> 0 | X19: =Y19*$BB19/100 -> 0 | Z19: =AA19+AB19 -> 0 | AA19: =AC19*$BA19/100 -> 0 | AB19: =AC19*$BB19/100 -> 0 | AD19: =AE19+AF19 -> 0 | AE19: =AG19*$BA19/100 -> 0 | AF19: =AG19*$BB19/100 -> 0 | AH19: =AI19+AJ19 -> 0 | AI19: =AK19*$BA19/100 -> 0 | AJ19: =AK19*$BB19/100 -> 0 | AL19: =AM19+AN19 -> 0 | AM19: =AO19*$BA19/100 -> 0 | AN19: =AO19*$BB19/100 -> 0 | AP19: =AQ19+AR19 -> 0 | AQ19: =AS19*$BA19/100 -> 0 | AR19: =AS19*$BB19/100 -> 0 | AT19: =AU19+AV19 -> 0 | AU19: =AW19*$BA19/100 -> 0 | AV19: =AW19*$BB19/100 -> 0 | AX19: =B19+F19+J19+N19+R19+V19+Z19+AD19+AH19+AL19+AP19+AT19 -> 200.7 | AY19: =C19+G19+K19+O19+S19+W19+AA19+AE19+AI19+AM19+AQ19+AU19 -> 200.7 | AZ19: =D19+H19+L19+P19+T19+X19+AB19+AF19+AJ19+AN19+AR19+AV19 -> 0 | BA19: =BC$1 -> 100 | BB19: =100-BA19 -> 0 | BC19: =AX19*(BB19/100) -> 0
A20: TOTAL | B20: =SUM(B17:B19) -> 200.7 | C20: =SUM(C17:C19) -> 200.7 | D20: =SUM(D17:D19) -> 0 | E20: =SUM(E17:E19) -> 200.7 | F20: =SUM(F17:F19) -> 0 | G20: =SUM(G17:G19) -> 0 | H20: =SUM(H17:H19) -> 0 | I20: =SUM(I17:I19) -> 0 | ... AW20: =SUM(AW17:AW19) -> 0 | AX20: =B20+F20+J20+N20+R20+V20+Z20+AD20+AH20+AL20+AP20+AT20 -> 1105.73 | AY20: =C20+G20+K20+O20+S20+W20+AA20+AE20+AI20+AM20+AQ20+AU20 -> 1105.73 | AZ20: =D20+H20+L20+P20+T20+X20+AB20+AF20+AJ20+AN20+AR20+AV20 -> 0 | BC20: =SUM(BC16:BC19) -> 0
A21: MANUTENÇÃO
A22: Manutenção | B22: =C22+D22 -> 0 | C22: =E22*$BA22/100 -> 0 | D22: =E22*$BB22/100 -> 0 | F22: =G22+H22 -> 0 | G22: =I22*$BA22/100 -> 0 | H22: =I22*$BB22/100 -> 0 | J22: =K22+L22 -> 0 | K22: =M22*$BA22/100 -> 0 | L22: =M22*$BB22/100 -> 0 | N22: =O22+P22 -> 0 | O22: =Q22*$BA22/100 -> 0 | P22: =Q22*$BB22/100 -> 0 | R22: =S22+T22 -> 0 | S22: =U22*$BA22/100 -> 0 | T22: =U22*$BB22/100 -> 0 | V22: =W22+X22 -> 0 | W22: =Y22*$BA22/100 -> 0 | X22: =Y22*$BB22/100 -> 0 | Z22: =AA22+AB22 -> 0 | AA22: =AC22*$BA22/100 -> 0 | AB22: =AC22*$BB22/100 -> 0 | AD22: =AE22+AF22 -> 0 | AE22: =AG22*$BA22/100 -> 0 | AF22: =AG22*$BB22/100 -> 0 | AH22: =AI22+AJ22 -> 0 | AI22: =AK22*$BA22/100 -> 0 | AJ22: =AK22*$BB22/100 -> 0 | AL22: =AM22+AN22 -> 0 | AM22: =AO22*$BA22/100 -> 0 | AN22: =AO22*$BB22/100 -> 0 | AP22: =AQ22+AR22 -> 0 | AQ22: =AS22*$BA22/100 -> 0 | AR22: =AS22*$BB22/100 -> 0 | AT22: =AU22+AV22 -> 0 | AU22: =AW22*$BA22/100 -> 0 | AV22: =AW22*$BB22/100 -> 0 | AX22: =B22+F22+J22+N22+R22+V22+Z22+AD22+AH22+AL22+AP22+AT22 -> 0 | AY22: =C22+G22+K22+O22+S22+W22+AA22+AE22+AI22+AM22+AQ22+AU22 -> 0 | AZ22: =D22+H22+L22+P22+T22+X22+AB22+AF22+AJ22+AN22+AR22+AV22 -> 0 | BA22: =BC$1 -> 100 | BB22: =100-BA22 -> 0 | BC22: =AX22*(BB22/100) -> 0
A23: Manutenção dos Ar condicionados | B23: =C23+D23 -> 960.64 | C23: =E23*$BA23/100 -> 960.64 | D23: =E23*$BB23/100 -> 0 | E23: =780.52+180.12 -> 960.64 | F23: =G23+H23 -> 180 | G23: =I23*$BA23/100 -> 180 | H23: =I23*$BB23/100 -> 0 | I23: 180 | J23: =K23+L23 -> 180 | K23: =M23*$BA23/100 -> 180 | L23: =M23*$BB23/100 -> 0 | M23: 180 | N23: =O23+P23 -> 0 | O23: =Q23*$BA23/100 -> 0 | P23: =Q23*$BB23/100 -> 0 | R23: =S23+T23 -> 0 | S23: =U23*$BA23/100 -> 0 | T23: =U23*$BB23/100 -> 0 | V23: =W23+X23 -> 0 | W23: =Y23*$BA23/100 -> 0 | X23: =Y23*$BB23/100 -> 0 | Z23: =AA23+AB23 -> 0 | AA23: =AC23*$BA23/100 -> 0 | AB23: =AC23*$BB23/100 -> 0 | AD23: =AE23+AF23 -> 0 | AE23: =AG23*$BA23/100 -> 0 | AF23: =AG23*$BB23/100 -> 0 | AH23: =AI23+AJ23 -> 0 | AI23: =AK23*$BA23/100 -> 0 | AJ23: =AK23*$BB23/100 -> 0 | AL23: =AM23+AN23 -> 0 | AM23: =AO23*$BA23/100 -> 0 | AN23: =AO23*$BB23/100 -> 0 | AP23: =AQ23+AR23 -> 0 | AQ23: =AS23*$BA23/100 -> 0 | AR23: =AS23*$BB23/100 -> 0 | AT23: =AU23+AV23 -> 0 | AU23: =AW23*$BA23/100 -> 0 | AV23: =AW23*$BB23/100 -> 0 | AX23: =B23+F23+J23+N23+R23+V23+Z23+AD23+AH23+AL23+AP23+AT23 -> 1320.64 | AY23: =C23+G23+K23+O23+S23+W23+AA23+AE23+AI23+AM23+AQ23+AU23 -> 1320.64 | AZ23: =D23+H23+L23+P23+T23+X23+AB23+AF23+AJ23+AN23+AR23+AV23 -> 0 | BA23: =BC$1 -> 100 | BB23: =100-BA23 -> 0 | BC23: =AX23*(BB23/100) -> 0
A24: Manutenção dos computadores | B24: =C24+D24 -> 0 | C24: =E24*$BA24/100 -> 0 | D24: =E24*$BB24/100 -> 0 | F24: =G24+H24 -> 0 | G24: =I24*$BA24/100 -> 0 | H24: =I24*$BB24/100 -> 0 | J24: =K24+L24 -> 0 | K24: =M24*$BA24/100 -> 0 | L24: =M24*$BB24/100 -> 0 | N24: =O24+P24 -> 0 | O24: =Q24*$BA24/100 -> 0 | P24: =Q24*$BB24/100 -> 0 | R24: =S24+T24 -> 0 | S24: =U24*$BA24/100 -> 0 | T24: =U24*$BB24/100 -> 0 | V24: =W24+X24 -> 0 | W24: =Y24*$BA24/100 -> 0 | X24: =Y24*$BB24/100 -> 0 | Z24: =AA24+AB24 -> 0 | AA24: =AC24*$BA24/100 -> 0 | AB24: =AC24*$BB24/100 -> 0 | AD24: =AE24+AF24 -> 0 | AE24: =AG24*$BA24/100 -> 0 | AF24: =AG24*$BB24/100 -> 0 | AH24: =AI24+AJ24 -> 0 | AI24: =AK24*$BA24/100 -> 0 | AJ24: =AK24*$BB24/100 -> 0 | AL24: =AM24+AN24 -> 0 | AM24: =AO24*$BA24/100 -> 0 | AN24: =AO24*$BB24/100 -> 0 | AP24: =AQ24+AR24 -> 0 | AQ24: =AS24*$BA24/100 -> 0 | AR24: =AS24*$BB24/100 -> 0 | AT24: =AU24+AV24 -> 0 | AU24: =AW24*$BA24/100 -> 0 | AV24: =AW24*$BB24/100 -> 0 | AX24: =B24+F24+J24+N24+R24+V24+Z24+AD24+AH24+AL24+AP24+AT24 -> 0 | AY24: =C24+G24+K24+O24+S24+W24+AA24+AE24+AI24+AM24+AQ24+AU24 -> 0 | AZ24: =D24+H24+L24+P24+T24+X24+AB24+AF24+AJ24+AN24+AR24+AV24 -> 0 | BA24: =BC$1 -> 100 | BB24: =100-BA24 -> 0 | BC24: =AX24*(BB24/100) -> 0
A25: Manutenção da Telefonia | B25: =C25+D25 -> 519.98 | C25: =E25*$BA25/100 -> 519.98 | D25: =E25*$BB25/100 -> 0 | E25: =460+59.98 -> 519.98 | F25: =G25+H25 -> 0 | G25: =I25*$BA25/100 -> 0 | H25: =I25*$BB25/100 -> 0 | J25: =K25+L25 -> 0 | K25: =M25*$BA25/100 -> 0 | L25: =M25*$BB25/100 -> 0 | N25: =O25+P25 -> 0 | O25: =Q25*$BA25/100 -> 0 | P25: =Q25*$BB25/100 -> 0 | R25: =S25+T25 -> 0 | S25: =U25*$BA25/100 -> 0 | T25: =U25*$BB25/100 -> 0 | V25: =W25+X25 -> 0 | W25: =Y25*$BA25/100 -> 0 | X25: =Y25*$BB25/100 -> 0 | Z25: =AA25+AB25 -> 0 | AA25: =AC25*$BA25/100 -> 0 | AB25: =AC25*$BB25/100 -> 0 | AD25: =AE25+AF25 -> 0 | AE25: =AG25*$BA25/100 -> 0 | AF25: =AG25*$BB25/100 -> 0 | AH25: =AI25+AJ25 -> 0 | AI25: =AK25*$BA25/100 -> 0 | AJ25: =AK25*$BB25/100 -> 0 | AL25: =AM25+AN25 -> 0 | AM25: =AO25*$BA25/100 -> 0 | AN25: =AO25*$BB25/100 -> 0 | AP25: =AQ25+AR25 -> 0 | AQ25: =AS25*$BA25/100 -> 0 | AR25: =AS25*$BB25/100 -> 0 | AT25: =AU25+AV25 -> 0 | AU25: =AW25*$BA25/100 -> 0 | AV25: =AW25*$BB25/100 -> 0 | AX25: =B25+F25+J25+N25+R25+V25+Z25+AD25+AH25+AL25+AP25+AT25 -> 519.98 | AY25: =C25+G25+K25+O25+S25+W25+AA25+AE25+AI25+AM25+AQ25+AU25 -> 519.98 | AZ25: =D25+H25+L25+P25+T25+X25+AB25+AF25+AJ25+AN25+AR25+AV25 -> 0 | BA25: =BC$1 -> 100 | BB25: =100-BA25 -> 0 | BC25: =AX25*(BB25/100) -> 0
A26: Outro | B26: =C26+D26 -> 0 | C26: =E26*$BA26/100 -> 0 | D26: =E26*$BB26/100 -> 0 | F26: =G26+H26 -> 0 | G26: =I26*$BA26/100 -> 0 | H26: =I26*$BB26/100 -> 0 | J26: =K26+L26 -> 0 | K26: =M26*$BA26/100 -> 0 | L26: =M26*$BB26/100 -> 0 | N26: =O26+P26 -> 0 | O26: =Q26*$BA26/100 -> 0 | P26: =Q26*$BB26/100 -> 0 | R26: =S26+T26 -> 0 | S26: =U26*$BA26/100 -> 0 | T26: =U26*$BB26/100 -> 0 | V26: =W26+X26 -> 0 | W26: =Y26*$BA26/100 -> 0 | X26: =Y26*$BB26/100 -> 0 | Z26: =AA26+AB26 -> 0 | AA26: =AC26*$BA26/100 -> 0 | AB26: =AC26*$BB26/100 -> 0 | AD26: =AE26+AF26 -> 0 | AE26: =AG26*$BA26/100 -> 0 | AF26: =AG26*$BB26/100 -> 0 | AH26: =AI26+AJ26 -> 0 | AI26: =AK26*$BA26/100 -> 0 | AJ26: =AK26*$BB26/100 -> 0 | AL26: =AM26+AN26 -> 0 | AM26: =AO26*$BA26/100 -> 0 | AN26: =AO26*$BB26/100 -> 0 | AP26: =AQ26+AR26 -> 0 | AQ26: =AS26*$BA26/100 -> 0 | AR26: =AS26*$BB26/100 -> 0 | AT26: =AU26+AV26 -> 0 | AU26: =AW26*$BA26/100 -> 0 | AV26: =AW26*$BB26/100 -> 0 | AX26: =B26+F26+J26+N26+R26+V26+Z26+AD26+AH26+AL26+AP26+AT26 -> 0 | AY26: =C26+G26+K26+O26+S26+W26+AA26+AE26+AI26+AM26+AQ26+AU26 -> 0 | AZ26: =D26+H26+L26+P26+T26+X26+AB26+AF26+AJ26+AN26+AR26+AV26 -> 0 | BA26: =BC$1 -> 100 | BB26: =100-BA26 -> 0 | BC26: =AX26*(BB26/100) -> 0
A27: TOTAL | B27: =SUM(B22:B26) -> 1480.62 | C27: =SUM(C22:C26) -> 1480.62 | D27: =SUM(D22:D26) -> 0 | E27: =SUM(E22:E26) -> 1480.62 | F27: =SUM(F22:F26) -> 180 | G27: =SUM(G22:G26) -> 180 | H27: =SUM(H22:H26) -> 0 | I27: =SUM(I22:I26) -> 180 | ... AW27: =SUM(AW22:AW26) -> 0 | AX27: =B27+F27+J27+N27+R27+V27+Z27+AD27+AH27+AL27+AP27+AT27 -> 1840.62 | AY27: =C27+G27+K27+O27+S27+W27+AA27+AE27+AI27+AM27+AQ27+AU27 -> 1840.62 | AZ27: =D27+H27+L27+P27+T27+X27+AB27+AF27+AJ27+AN27+AR27+AV27 -> 0 | BC27: =SUM(BC21:BC26) -> 0
A28: TOTAL CONTAS DE CONSUMO | B28: =B15+B20+B27 -> 21755.45 | C28: =C15+C20+C27 -> 21462.07 | D28: =D15+D20+D27 -> 293.38 | E28: =E15+E20+E27 -> 21755.45 | F28: =F15+F20+F27 -> 19730.98 | G28: =G15+G20+G27 -> 19430.48 | H28: =H15+H20+H27 -> 300.5 | I28: =I15+I20+I27 -> 19730.98 | ... AW28: =AW15+AW20+AW27 -> 0 | AX28: =B28+F28+J28+N28+R28+V28+Z28+AD28+AH28+AL28+AP28+AT28 -> 45541.07 | AY28: =C28+G28+K28+O28+S28+W28+AA28+AE28+AI28+AM28+AQ28+AU28 -> 44554.95 | AZ28: =D28+H28+L28+P28+T28+X28+AB28+AF28+AJ28+AN28+AR28+AV28 -> 986.12 | BC28: =BC15+BC20+BC27 -> 0
A29: CONTAS OPERACIONAIS VENDA
A30: ASSOCI | B30: =C30+D30 -> 0 | F30: =G30+H30 -> 0 | J30: =K30+L30 -> 0 | N30: =O30+P30 -> 0 | R30: =S30+T30 -> 0 | V30: =W30+X30 -> 0 | Z30: =AA30+AB30 -> 0 | AD30: =AE30+AF30 -> 0 | AH30: =AI30+AJ30 -> 0 | AL30: =AM30+AN30 -> 0 | AP30: =AQ30+AR30 -> 0 | AT30: =AU30+AV30 -> 0 | AX30: =B30+F30+J30+N30+R30+V30+Z30+AD30+AH30+AL30+AP30+AT30 -> 0 | AY30: =C30+G30+K30+O30+S30+W30+AA30+AE30+AI30+AM30+AQ30+AU30 -> 0 | AZ30: =D30+H30+L30+P30+T30+X30+AB30+AF30+AJ30+AN30+AR30+AV30 -> 0
A31: Ação de marketing / material de divulgação | B31: =C31+D31 -> 0 | F31: =G31+H31 -> 0 | J31: =K31+L31 -> 0 | N31: =O31+P31 -> 0 | R31: =S31+T31 -> 0 | V31: =W31+X31 -> 0 | Z31: =AA31+AB31 -> 0 | AD31: =AE31+AF31 -> 0 | AH31: =AI31+AJ31 -> 0 | AL31: =AM31+AN31 -> 0 | AP31: =AQ31+AR31 -> 0 | AT31: =AU31+AV31 -> 0 | AX31: =B31+F31+J31+N31+R31+V31+Z31+AD31+AH31+AL31+AP31+AT31 -> 0 | AY31: =C31+G31+K31+O31+S31+W31+AA31+AE31+AI31+AM31+AQ31+AU31 -> 0 | AZ31: =D31+H31+L31+P31+T31+X31+AB31+AF31+AJ31+AN31+AR31+AV31 -> 0
A32: Assinatura Digital/aplicativo | B32: =C32+D32 -> 0 | F32: =G32+H32 -> 0 | J32: =K32+L32 -> 0 | N32: =O32+P32 -> 0 | R32: =S32+T32 -> 0 | V32: =W32+X32 -> 0 | Z32: =AA32+AB32 -> 0 | AD32: =AE32+AF32 -> 0 | AH32: =AI32+AJ32 -> 0 | AL32: =AM32+AN32 -> 0 | AP32: =AQ32+AR32 -> 0 | AT32: =AU32+AV32 -> 0 | AX32: =B32+F32+J32+N32+R32+V32+Z32+AD32+AH32+AL32+AP32+AT32 -> 0 | AY32: =C32+G32+K32+O32+S32+W32+AA32+AE32+AI32+AM32+AQ32+AU32 -> 0 | AZ32: =D32+H32+L32+P32+T32+X32+AB32+AF32+AJ32+AN32+AR32+AV32 -> 0
A33: Café para Equipe | B33: =C33+D33 -> 226.92 | C33: =127.39+99.53 -> 226.92 | F33: =G33+H33 -> 437.46 | G33: =379.53+57.93 -> 437.46 | J33: =K33+L33 -> 0 | N33: =O33+P33 -> 0 | R33: =S33+T33 -> 0 | V33: =W33+X33 -> 0 | Z33: =AA33+AB33 -> 0 | AD33: =AE33+AF33 -> 0 | AH33: =AI33+AJ33 -> 0 | AL33: =AM33+AN33 -> 0 | AP33: =AQ33+AR33 -> 0 | AT33: =AU33+AV33 -> 0 | AX33: =B33+F33+J33+N33+R33+V33+Z33+AD33+AH33+AL33+AP33+AT33 -> 664.38 | AY33: =C33+G33+K33+O33+S33+W33+AA33+AE33+AI33+AM33+AQ33+AU33 -> 664.38 | AZ33: =D33+H33+L33+P33+T33+X33+AB33+AF33+AJ33+AN33+AR33+AV33 -> 0
A34: Campanha Agenciamento (voulcher p almço) | B34: =C34+D34 -> 0 | F34: =G34+H34 -> 0 | J34: =K34+L34 -> 0 | N34: =O34+P34 -> 0 | R34: =S34+T34 -> 0 | V34: =W34+X34 -> 0 | Z34: =AA34+AB34 -> 0 | AD34: =AE34+AF34 -> 0 | AH34: =AI34+AJ34 -> 0 | AL34: =AM34+AN34 -> 0 | AP34: =AQ34+AR34 -> 0 | AT34: =AU34+AV34 -> 0 | AX34: =B34+F34+J34+N34+R34+V34+Z34+AD34+AH34+AL34+AP34+AT34 -> 0 | AY34: =C34+G34+K34+O34+S34+W34+AA34+AE34+AI34+AM34+AQ34+AU34 -> 0 | AZ34: =D34+H34+L34+P34+T34+X34+AB34+AF34+AJ34+AN34+AR34+AV34 -> 0
A35: Campanha Semestral | B35: =C35+D35 -> 0 | F35: =G35+H35 -> 0 | J35: =K35+L35 -> 0 | N35: =O35+P35 -> 0 | R35: =S35+T35 -> 0 | V35: =W35+X35 -> 0 | Z35: =AA35+AB35 -> 0 | AD35: =AE35+AF35 -> 0 | AH35: =AI35+AJ35 -> 0 | AL35: =AM35+AN35 -> 0 | AP35: =AQ35+AR35 -> 0 | AT35: =AU35+AV35 -> 0 | AX35: =B35+F35+J35+N35+R35+V35+Z35+AD35+AH35+AL35+AP35+AT35 -> 0 | AY35: =C35+G35+K35+O35+S35+W35+AA35+AE35+AI35+AM35+AQ35+AU35 -> 0 | AZ35: =D35+H35+L35+P35+T35+X35+AB35+AF35+AJ35+AN35+AR35+AV35 -> 0
A36: Campanhas outras | B36: =C36+D36 -> 0 | F36: =G36+H36 -> 0 | J36: =K36+L36 -> 0 | N36: =O36+P36 -> 0 | R36: =S36+T36 -> 0 | V36: =W36+X36 -> 0 | Z36: =AA36+AB36 -> 0 | AD36: =AE36+AF36 -> 0 | AH36: =AI36+AJ36 -> 0 | AL36: =AM36+AN36 -> 0 | AP36: =AQ36+AR36 -> 0 | AT36: =AU36+AV36 -> 0 | AX36: =B36+F36+J36+N36+R36+V36+Z36+AD36+AH36+AL36+AP36+AT36 -> 0 | AY36: =C36+G36+K36+O36+S36+W36+AA36+AE36+AI36+AM36+AQ36+AU36 -> 0 | AZ36: =D36+H36+L36+P36+T36+X36+AB36+AF36+AJ36+AN36+AR36+AV36 -> 0
A37: Cartões de visita | B37: =C37+D37 -> 0 | F37: =G37+H37 -> 0 | J37: =K37+L37 -> 0 | N37: =O37+P37 -> 0 | R37: =S37+T37 -> 0 | V37: =W37+X37 -> 0 | Z37: =AA37+AB37 -> 0 | AD37: =AE37+AF37 -> 0 | AH37: =AI37+AJ37 -> 0 | AL37: =AM37+AN37 -> 0 | AP37: =AQ37+AR37 -> 0 | AT37: =AU37+AV37 -> 0 | AX37: =B37+F37+J37+N37+R37+V37+Z37+AD37+AH37+AL37+AP37+AT37 -> 0 | AY37: =C37+G37+K37+O37+S37+W37+AA37+AE37+AI37+AM37+AQ37+AU37 -> 0 | AZ37: =D37+H37+L37+P37+T37+X37+AB37+AF37+AJ37+AN37+AR37+AV37 -> 0
A38: Certidões/procuração/matrículas | B38: =C38+D38 -> 0 | F38: =G38+H38 -> 0 | J38: =K38+L38 -> 0 | N38: =O38+P38 -> 0 | R38: =S38+T38 -> 0 | V38: =W38+X38 -> 0 | Z38: =AA38+AB38 -> 0 | AD38: =AE38+AF38 -> 0 | AH38: =AI38+AJ38 -> 0 | AI38: =-26.45+26.45 -> 0 | AL38: =AM38+AN38 -> 0 | AP38: =AQ38+AR38 -> 0 | AT38: =AU38+AV38 -> 0 | AX38: =B38+F38+J38+N38+R38+V38+Z38+AD38+AH38+AL38+AP38+AT38 -> 0 | AY38: =C38+G38+K38+O38+S38+W38+AA38+AE38+AI38+AM38+AQ38+AU38 -> 0 | AZ38: =D38+H38+L38+P38+T38+X38+AB38+AF38+AJ38+AN38+AR38+AV38 -> 0
A39: CHAVE NA MÃO | B39: =C39+D39 -> 0 | F39: =G39+H39 -> 0 | J39: =K39+L39 -> 0 | N39: =O39+P39 -> 0 | R39: =S39+T39 -> 0 | V39: =W39+X39 -> 0 | Z39: =AA39+AB39 -> 0 | AD39: =AE39+AF39 -> 0 | AH39: =AI39+AJ39 -> 0 | AL39: =AM39+AN39 -> 0 | AP39: =AQ39+AR39 -> 0 | AT39: =AU39+AV39 -> 0 | AX39: =B39+F39+J39+N39+R39+V39+Z39+AD39+AH39+AL39+AP39+AT39 -> 0 | AY39: =C39+G39+K39+O39+S39+W39+AA39+AE39+AI39+AM39+AQ39+AU39 -> 0 | AZ39: =D39+H39+L39+P39+T39+X39+AB39+AF39+AJ39+AN39+AR39+AV39 -> 0
A40: Chaveiros (identicação de chaves) | B40: =C40+D40 -> 0 | F40: =G40+H40 -> 0 | J40: =K40+L40 -> 0 | N40: =O40+P40 -> 0 | R40: =S40+T40 -> 0 | V40: =W40+X40 -> 0 | Z40: =AA40+AB40 -> 0 | AD40: =AE40+AF40 -> 0 | AH40: =AI40+AJ40 -> 0 | AL40: =AM40+AN40 -> 0 | AP40: =AQ40+AR40 -> 0 | AT40: =AU40+AV40 -> 0 | AX40: =B40+F40+J40+N40+R40+V40+Z40+AD40+AH40+AL40+AP40+AT40 -> 0 | AY40: =C40+G40+K40+O40+S40+W40+AA40+AE40+AI40+AM40+AQ40+AU40 -> 0 | AZ40: =D40+H40+L40+P40+T40+X40+AB40+AF40+AJ40+AN40+AR40+AV40 -> 0
...

Sheet FOLHA DE PAGAMENTOS
B1: 46023 | F1: 46054 | J1: 46082 | N1: 46113 | R1: 46143 | V1: 46174 | Z1: 46204 | AD1: 46235 | AH1: 46266 | AL1: 46296 | AP1: 46327 | AT1: 46357 | AY1: VENDA | AZ1: LOCAÇÃO
B2: TOTAL | C2: VENDA | D2: ALUGUEL | F2: TOTAL | G2: VENDA | H2: ALUGUEL | J2: TOTAL | K2: VENDA | L2: ALUGUEL | N2: TOTAL | O2: VENDA | P2: ALUGUEL | R2: TOTAL | S2: VENDA | T2: ALUGUEL | V2: TOTAL | W2: VENDA | X2: ALUGUEL | Z2: TOTAL | AA2: VENDA | AB2: ALUGUEL | AD2: TOTAL | AE2: VENDA | AF2: ALUGUEL | AH2: TOTAL | AI2: VENDA | AJ2: ALUGUEL | AL2: TOTAL | AM2: VENDA | AN2: ALUGUEL | AP2: TOTAL | AQ2: VENDA | AR2: ALUGUEL | AT2: TOTAL | AU2: VENDA | AV2: ALUGUEL | AX2: TOTAL | AY2: VENDA | AZ2: ALUGUEL
A3: FOLHA DE PAGAMENTO VENDA
A4: CIEE/Agiel | B4: =C4+D4 -> 0 | F4: =G4+H4 -> 0 | J4: =K4+L4 -> 0 | N4: =O4+P4 -> 0 | R4: =S4+T4 -> 0 | V4: =W4+X4 -> 0 | Z4: =AA4+AB4 -> 0 | AD4: =AE4+AF4 -> 0 | AH4: =AI4+AJ4 -> 0 | AL4: =AM4+AN4 -> 0 | AP4: =AQ4+AR4 -> 0 | AT4: =AU4+AV4 -> 0 | AX4: =AY4+AZ4 -> 0 | AY4: =C4+G4+K4+O4+S4+W4+AA4+AE4+AI4+AM4+AQ4+AU4 -> 0 | AZ4: =D4+H4+L4+P4+T4+X4+AB4+AF4+AJ4+AN4+AR4+AV4 -> 0
A5: Estagio-seguro | B5: =C5+D5 -> 0 | F5: =G5+H5 -> 0 | J5: =K5+L5 -> 0 | N5: =O5+P5 -> 0 | R5: =S5+T5 -> 0 | V5: =W5+X5 -> 0 | Z5: =AA5+AB5 -> 0 | AD5: =AE5+AF5 -> 0 | AH5: =AI5+AJ5 -> 0 | AL5: =AM5+AN5 -> 0 | AP5: =AQ5+AR5 -> 0 | AT5: =AU5+AV5 -> 0 | AX5: =AY5+AZ5 -> 0 | AY5: =C5+G5+K5+O5+S5+W5+AA5+AE5+AI5+AM5+AQ5+AU5 -> 0 | AZ5: =D5+H5+L5+P5+T5+X5+AB5+AF5+AJ5+AN5+AR5+AV5 -> 0
A6: Pro-labore | B6: =C6+D6 -> 0 | F6: =G6+H6 -> 0 | J6: =K6+L6 -> 0 | N6: =O6+P6 -> 0 | R6: =S6+T6 -> 0 | V6: =W6+X6 -> 0 | Z6: =AA6+AB6 -> 0 | AD6: =AE6+AF6 -> 0 | AH6: =AI6+AJ6 -> 0 | AL6: =AM6+AN6 -> 0 | AP6: =AQ6+AR6 -> 0 | AT6: =AU6+AV6 -> 0 | AX6: =AY6+AZ6 -> 0 | AY6: =C6+G6+K6+O6+S6+W6+AA6+AE6+AI6+AM6+AQ6+AU6 -> 0 | AZ6: =D6+H6+L6+P6+T6+X6+AB6+AF6+AJ6+AN6+AR6+AV6 -> 0
A7: Contratos - Rafael | B7: =C7+D7 -> 0 | F7: =G7+H7 -> 0 | J7: =K7+L7 -> 0 | N7: =O7+P7 -> 0 | R7: =S7+T7 -> 0 | V7: =W7+X7 -> 0 | Z7: =AA7+AB7 -> 0 | AD7: =AE7+AF7 -> 0 | AH7: =AI7+AJ7 -> 0 | AL7: =AM7+AN7 -> 0 | AP7: =AQ7+AR7 -> 0 | AT7: =AU7+AV7 -> 0 | AX7: =AY7+AZ7 -> 0 | AY7: =C7+G7+K7+O7+S7+W7+AA7+AE7+AI7+AM7+AQ7+AU7 -> 0 | AZ7: =D7+H7+L7+P7+T7+X7+AB7+AF7+AJ7+AN7+AR7+AV7 -> 0
A8: VA | B8: =C8+D8 -> 0 | F8: =G8+H8 -> 0 | J8: =K8+L8 -> 0 | N8: =O8+P8 -> 0 | R8: =S8+T8 -> 0 | V8: =W8+X8 -> 0 | Z8: =AA8+AB8 -> 0 | AD8: =AE8+AF8 -> 0 | AH8: =AI8+AJ8 -> 0 | AL8: =AM8+AN8 -> 0 | AP8: =AQ8+AR8 -> 0 | AT8: =AU8+AV8 -> 0 | AX8: =AY8+AZ8 -> 0 | AY8: =C8+G8+K8+O8+S8+W8+AA8+AE8+AI8+AM8+AQ8+AU8 -> 0 | AZ8: =D8+H8+L8+P8+T8+X8+AB8+AF8+AJ8+AN8+AR8+AV8 -> 0
A9: VT | B9: =C9+D9 -> 0 | F9: =G9+H9 -> 0 | J9: =K9+L9 -> 0 | N9: =O9+P9 -> 0 | R9: =S9+T9 -> 0 | V9: =W9+X9 -> 0 | Z9: =AA9+AB9 -> 0 | AD9: =AE9+AF9 -> 0 | AH9: =AI9+AJ9 -> 0 | AL9: =AM9+AN9 -> 0 | AP9: =AQ9+AR9 -> 0 | AT9: =AU9+AV9 -> 0 | AX9: =AY9+AZ9 -> 0 | AY9: =C9+G9+K9+O9+S9+W9+AA9+AE9+AI9+AM9+AQ9+AU9 -> 0 | AZ9: =D9+H9+L9+P9+T9+X9+AB9+AF9+AJ9+AN9+AR9+AV9 -> 0
A10: Recepção | B10: =C10+D10 -> 0 | F10: =G10+H10 -> 0 | J10: =K10+L10 -> 0 | N10: =O10+P10 -> 0 | R10: =S10+T10 -> 0 | V10: =W10+X10 -> 0 | Z10: =AA10+AB10 -> 0 | AD10: =AE10+AF10 -> 0 | AH10: =AI10+AJ10 -> 0 | AL10: =AM10+AN10 -> 0 | AP10: =AQ10+AR10 -> 0 | AT10: =AU10+AV10 -> 0 | AX10: =AY10+AZ10 -> 0 | AY10: =C10+G10+K10+O10+S10+W10+AA10+AE10+AI10+AM10+AQ10+AU10 -> 0 | AZ10: =D10+H10+L10+P10+T10+X10+AB10+AF10+AJ10+AN10+AR10+AV10 -> 0
A11: VA | B11: =C11+D11 -> 0 | F11: =G11+H11 -> 0 | J11: =K11+L11 -> 0 | N11: =O11+P11 -> 0 | R11: =S11+T11 -> 0 | V11: =W11+X11 -> 0 | Z11: =AA11+AB11 -> 0 | AD11: =AE11+AF11 -> 0 | AH11: =AI11+AJ11 -> 0 | AL11: =AM11+AN11 -> 0 | AP11: =AQ11+AR11 -> 0 | AT11: =AU11+AV11 -> 0 | AX11: =AY11+AZ11 -> 0 | AY11: =C11+G11+K11+O11+S11+W11+AA11+AE11+AI11+AM11+AQ11+AU11 -> 0 | AZ11: =D11+H11+L11+P11+T11+X11+AB11+AF11+AJ11+AN11+AR11+AV11 -> 0
A12: VT | B12: =C12+D12 -> 0 | F12: =G12+H12 -> 0 | J12: =K12+L12 -> 0 | N12: =O12+P12 -> 0 | R12: =S12+T12 -> 0 | V12: =W12+X12 -> 0 | Z12: =AA12+AB12 -> 0 | AD12: =AE12+AF12 -> 0 | AH12: =AI12+AJ12 -> 0 | AL12: =AM12+AN12 -> 0 | AP12: =AQ12+AR12 -> 0 | AT12: =AU12+AV12 -> 0 | AX12: =AY12+AZ12 -> 0 | AY12: =C12+G12+K12+O12+S12+W12+AA12+AE12+AI12+AM12+AQ12+AU12 -> 0 | AZ12: =D12+H12+L12+P12+T12+X12+AB12+AF12+AJ12+AN12+AR12+AV12 -> 0
A13: substituição das Férias | B13: =C13+D13 -> 0 | F13: =G13+H13 -> 0 | J13: =K13+L13 -> 0 | N13: =O13+P13 -> 0 | R13: =S13+T13 -> 0 | V13: =W13+X13 -> 0 | Z13: =AA13+AB13 -> 0 | AD13: =AE13+AF13 -> 0 | AH13: =AI13+AJ13 -> 0 | AL13: =AM13+AN13 -> 0 | AP13: =AQ13+AR13 -> 0 | AT13: =AU13+AV13 -> 0 | AX13: =AY13+AZ13 -> 0 | AY13: =C13+G13+K13+O13+S13+W13+AA13+AE13+AI13+AM13+AQ13+AU13 -> 0 | AZ13: =D13+H13+L13+P13+T13+X13+AB13+AF13+AJ13+AN13+AR13+AV13 -> 0
A14: Recepção- Giovana | B14: =C14+D14 -> 0 | F14: =G14+H14 -> 0 | J14: =K14+L14 -> 0 | N14: =O14+P14 -> 0 | R14: =S14+T14 -> 0 | V14: =W14+X14 -> 0 | Z14: =AA14+AB14 -> 0 | AD14: =AE14+AF14 -> 0 | AH14: =AI14+AJ14 -> 0 | AL14: =AM14+AN14 -> 0 | AP14: =AQ14+AR14 -> 0 | AT14: =AU14+AV14 -> 0 | AX14: =AY14+AZ14 -> 0 | AY14: =C14+G14+K14+O14+S14+W14+AA14+AE14+AI14+AM14+AQ14+AU14 -> 0 | AZ14: =D14+H14+L14+P14+T14+X14+AB14+AF14+AJ14+AN14+AR14+AV14 -> 0
A15: VA | B15: =C15+D15 -> 0 | F15: =G15+H15 -> 0 | J15: =K15+L15 -> 0 | N15: =O15+P15 -> 0 | R15: =S15+T15 -> 0 | V15: =W15+X15 -> 0 | Z15: =AA15+AB15 -> 0 | AD15: =AE15+AF15 -> 0 | AH15: =AI15+AJ15 -> 0 | AL15: =AM15+AN15 -> 0 | AP15: =AQ15+AR15 -> 0 | AT15: =AU15+AV15 -> 0 | AX15: =AY15+AZ15 -> 0 | AY15: =C15+G15+K15+O15+S15+W15+AA15+AE15+AI15+AM15+AQ15+AU15 -> 0 | AZ15: =D15+H15+L15+P15+T15+X15+AB15+AF15+AJ15+AN15+AR15+AV15 -> 0
... A19: VT | B19: =C19+D19 -> 0 | F19: =G19+H19 -> 0 | J19: =K19+L19 -> 0 | N19: =O19+P19 -> 0 | R19: =S19+T19 -> 0 | V19: =W19+X19 -> 0 | Z19: =AA19+AB19 -> 0 | AD19: =AE19+AF19 -> 0 | AH19: =AI19+AJ19 -> 0 | AL19: =AM19+AN19 -> 0 | AP19: =AQ19+AR19 -> 0 | AT19: =AU19+AV19 -> 0 | AX19: =AY19+AZ19 -> 0 | AY19: =C19+G19+K19+O19+S19+W19+AA19+AE19+AI19+AM19+AQ19+AU19 -> 0 | AZ19: =D19+H19+L19+P19+T19+X19+AB19+AF19+AJ19+AN19+AR19+AV19 -> 0
A20: TOTAL | B20: =SUM(B4:B19) -> 0 | C20: =SUM(C4:C19) -> 0 | D20: =SUM(D4:D19) -> 0 | F20: =SUM(F4:F19) -> 0 | G20: =SUM(G4:G19) -> 0 | H20: =SUM(H4:H19) -> 0 | J20: =SUM(J4:J19) -> 0 | K20: =SUM(K4:K19) -> 0 | L20: =SUM(L4:L19) -> 0 | N20: =SUM(N4:N19) -> 0 | O20: =SUM(O4:O19) -> 0 | P20: =SUM(P4:P19) -> 0 | R20: =SUM(R4:R19) -> 0 | S20: =SUM(S4:S19) -> 0 | T20: =SUM(T4:T19) -> 0 | V20: =SUM(V4:V19) -> 0 | W20: =SUM(W4:W19) -> 0 | X20: =SUM(X4:X19) -> 0 | Z20: =SUM(Z4:Z19) -> 0 | AA20: =SUM(AA4:AA19) -> 0 | AB20: =SUM(AB4:AB19) -> 0 | AD20: =SUM(AD4:AD19) -> 0 | AE20: =SUM(AE4:AE19) -> 0 | AF20: =SUM(AF4:AF19) -> 0 | AH20: =SUM(AH4:AH19) -> 0 | AI20: =SUM(AI4:AI19) -> 0 | AJ20: =SUM(AJ4:AJ19) -> 0 | AL20: =SUM(AL4:AL19) -> 0 | AM20: =SUM(AM4:AM19) -> 0 | AN20: =SUM(AN4:AN19) -> 0 | AP20: =SUM(AP4:AP19) -> 0 | AQ20: =SUM(AQ4:AQ19) -> 0 | AR20: =SUM(AR4:AR19) -> 0 | AT20: =SUM(AT4:AT19) -> 0 | AU20: =SUM(AU4:AU19) -> 0 | AV20: =SUM(AV4:AV19) -> 0 | AX20: =SUM(AX4:AX19) -> 0 | AY20: =SUM(AY4:AY19) -> 0 | AZ20: =SUM(AZ4:AZ19) -> 0
A21: FOLHA DE PAGAMENTO ALUGUEL
A22: Ana Paula - Consultora | B22: =C22+D22 -> 0 | F22: =G22+H22 -> 0 | J22: =K22+L22 -> 0 | N22: =O22+P22 -> 0 | R22: =S22+T22 -> 0 | V22: =W22+X22 -> 0 | Z22: =AA22+AB22 -> 0 | AD22: =AE22+AF22 -> 0 | AH22: =AI22+AJ22 -> 0 | AL22: =AM22+AN22 -> 0 | AP22: =AQ22+AR22 -> 0 | AT22: =AU22+AV22 -> 0 | AX22: =AY22+AZ22 -> 0 | AY22: =C22+G22+K22+O22+S22+W22+AA22+AE22+AI22+AM22+AQ22+AU22 -> 0 | AZ22: =D22+H22+L22+P22+T22+X22+AB22+AF22+AJ22+AN22+AR22+AV22 -> 0
A23: VA | B23: =C23+D23 -> 0 | F23: =G23+H23 -> 0 | J23: =K23+L23 -> 0 | N23: =O23+P23 -> 0 | R23: =S23+T23 -> 0 | V23: =W23+X23 -> 0 | Z23: =AA23+AB23 -> 0 | AD23: =AE23+AF23 -> 0 | AH23: =AI23+AJ23 -> 0 | AL23: =AM23+AN23 -> 0 | AP23: =AQ23+AR23 -> 0 | AT23: =AU23+AV23 -> 0 | AX23: =AY23+AZ23 -> 0 | AY23: =C23+G23+K23+O23+S23+W23+AA23+AE23+AI23+AM23+AQ23+AU23 -> 0 | AZ23: =D23+H23+L23+P23+T23+X23+AB23+AF23+AJ23+AN23+AR23+AV23 -> 0
A24: VT | B24: =C24+D24 -> 0 | F24: =G24+H24 -> 0 | J24: =K24+L24 -> 0 | N24: =O24+P24 -> 0 | R24: =S24+T24 -> 0 | V24: =W24+X24 -> 0 | Z24: =AA24+AB24 -> 0 | AD24: =AE24+AF24 -> 0 | AH24: =AI24+AJ24 -> 0 | AL24: =AM24+AN24 -> 0 | AP24: =AQ24+AR24 -> 0 | AT24: =AU24+AV24 -> 0 | AX24: =AY24+AZ24 -> 0 | AY24: =C24+G24+K24+O24+S24+W24+AA24+AE24+AI24+AM24+AQ24+AU24 -> 0 | AZ24: =D24+H24+L24+P24+T24+X24+AB24+AF24+AJ24+AN24+AR24+AV24 -> 0
A25: Roberta - Consultora | B25: =C25+D25 -> 0 | F25: =G25+H25 -> 0 | J25: =K25+L25 -> 0 | N25: =O25+P25 -> 0 | R25: =S25+T25 -> 0 | V25: =W25+X25 -> 0 | Z25: =AA25+AB25 -> 0 | AD25: =AE25+AF25 -> 0 | AH25: =AI25+AJ25 -> 0 | AL25: =AM25+AN25 -> 0 | AP25: =AQ25+AR25 -> 0 | AT25: =AU25+AV25 -> 0 | AX25: =AY25+AZ25 -> 0 | AY25: =C25+G25+K25+O25+S25+W25+AA25+AE25+AI25+AM25+AQ25+AU25 -> 0 | AZ25: =D25+H25+L25+P25+T25+X25+AB25+AF25+AJ25+AN25+AR25+AV25 -> 0
A26: VA | B26: =C26+D26 -> 0 | F26: =G26+H26 -> 0 | J26: =K26+L26 -> 0 | N26: =O26+P26 -> 0 | R26: =S26+T26 -> 0 | V26: =W26+X26 -> 0 | Z26: =AA26+AB26 -> 0 | AD26: =AE26+AF26 -> 0 | AH26: =AI26+AJ26 -> 0 | AL26: =AM26+AN26 -> 0 | AP26: =AQ26+AR26 -> 0 | AT26: =AU26+AV26 -> 0 | AX26: =AY26+AZ26 -> 0 | AY26: =C26+G26+K26+O26+S26+W26+AA26+AE26+AI26+AM26+AQ26+AU26 -> 0 | AZ26: =D26+H26+L26+P26+T26+X26+AB26+AF26+AJ26+AN26+AR26+AV26 -> 0
A27: VT | B27: =C27+D27 -> 0 | F27: =G27+H27 -> 0 | J27: =K27+L27 -> 0 | N27: =O27+P27 -> 0 | R27: =S27+T27 -> 0 | V27: =W27+X27 -> 0 | Z27: =AA27+AB27 -> 0 | AD27: =AE27+AF27 -> 0 | AH27: =AI27+AJ27 -> 0 | AL27: =AM27+AN27 -> 0 | AP27: =AQ27+AR27 -> 0 | AT27: =AU27+AV27 -> 0 | AX27: =AY27+AZ27 -> 0 | AY27: =C27+G27+K27+O27+S27+W27+AA27+AE27+AI27+AM27+AQ27+AU27 -> 0 | AZ27: =D27+H27+L27+P27+T27+X27+AB27+AF27+AJ27+AN27+AR27+AV27 -> 0
A28: Michele - Captadora | B28: =C28+D28 -> 0 | F28: =G28+H28 -> 0 | J28: =K28+L28 -> 0 | N28: =O28+P28 -> 0 | R28: =S28+T28 -> 0 | V28: =W28+X28 -> 0 | Z28: =AA28+AB28 -> 0 | AD28: =AE28+AF28 -> 0 | AH28: =AI28+AJ28 -> 0 | AL28: =AM28+AN28 -> 0 | AP28: =AQ28+AR28 -> 0 | AT28: =AU28+AV28 -> 0 | AX28: =AY28+AZ28 -> 0 | AY28: =C28+G28+K28+O28+S28+W28+AA28+AE28+AI28+AM28+AQ28+AU28 -> 0 | AZ28: =D28+H28+L28+P28+T28+X28+AB28+AF28+AJ28+AN28+AR28+AV28 -> 0
A29: VA | B29: =C29+D29 -> 0 | F29: =G29+H29 -> 0 | J29: =K29+L29 -> 0 | N29: =O29+P29 -> 0 | R29: =S29+T29 -> 0 | V29: =W29+X29 -> 0 | Z29: =AA29+AB29 -> 0 | AD29: =AE29+AF29 -> 0 | AH29: =AI29+AJ29 -> 0 | AL29: =AM29+AN29 -> 0 | AP29: =AQ29+AR29 -> 0 | AT29: =AU29+AV29 -> 0 | AX29: =AY29+AZ29 -> 0 | AY29: =C29+G29+K29+O29+S29+W29+AA29+AE29+AI29+AM29+AQ29+AU29 -> 0 | AZ29: =D29+H29+L29+P29+T29+X29+AB29+AF29+AJ29+AN29+AR29+AV29 -> 0
A30: VT | B30: =C30+D30 -> 0 | F30: =G30+H30 -> 0 | J30: =K30+L30 -> 0 | N30: =O30+P30 -> 0 | R30: =S30+T30 -> 0 | V30: =W30+X30 -> 0 | Z30: =AA30+AB30 -> 0 | AD30: =AE30+AF30 -> 0 | AH30: =AI30+AJ30 -> 0 | AL30: =AM30+AN30 -> 0 | AP30: =AQ30+AR30 -> 0 | AT30: =AU30+AV30 -> 0 | AX30: =AY30+AZ30 -> 0 | AY30: =C30+G30+K30+O30+S30+W30+AA30+AE30+AI30+AM30+AQ30+AU30 -> 0 | AZ30: =D30+H30+L30+P30+T30+X30+AB30+AF30+AJ30+AN30+AR30+AV30 -> 0
A31: Vitória - Captadora | B31: =C31+D31 -> 0 | F31: =G31+H31 -> 0 | J31: =K31+L31 -> 0 | N31: =O31+P31 -> 0 | R31: =S31+T31 -> 0 | V31: =W31+X31 -> 0 | Z31: =AA31+AB31 -> 0 | AD31: =AE31+AF31 -> 0 | AH31: =AI31+AJ31 -> 0 | AL31: =AM31+AN31 -> 0 | AP31: =AQ31+AR31 -> 0 | AT31: =AU31+AV31 -> 0 | AX31: =AY31+AZ31 -> 0 | AY31: =C31+G31+K31+O31+S31+W31+AA31+AE31+AI31+AM31+AQ31+AU31 -> 0 | AZ31: =D31+H31+L31+P31+T31+X31+AB31+AF31+AJ31+AN31+AR31+AV31 -> 0
A32: VA | B32: =C32+D32 -> 0 | F32: =G32+H32 -> 0 | J32: =K32+L32 -> 0 | N32: =O32+P32 -> 0 | R32: =S32+T32 -> 0 | V32: =W32+X32 -> 0 | Z32: =AA32+AB32 -> 0 | AD32: =AE32+AF32 -> 0 | AH32: =AI32+AJ32 -> 0 | AL32: =AM32+AN32 -> 0 | AP32: =AQ32+AR32 -> 0 | AT32: =AU32+AV32 -> 0 | AX32: =AY32+AZ32 -> 0 | AY32: =C32+G32+K32+O32+S32+W32+AA32+AE32+AI32+AM32+AQ32+AU32 -> 0 | AZ32: =D32+H32+L32+P32+T32+X32+AB32+AF32+AJ32+AN32+AR32+AV32 -> 0
A33: VT | B33: =C33+D33 -> 0 | F33: =G33+H33 -> 0 | J33: =K33+L33 -> 0 | N33: =O33+P33 -> 0 | R33: =S33+T33 -> 0 | V33: =W33+X33 -> 0 | Z33: =AA33+AB33 -> 0 | AD33: =AE33+AF33 -> 0 | AH33: =AI33+AJ33 -> 0 | AL33: =AM33+AN33 -> 0 | AP33: =AQ33+AR33 -> 0 | AT33: =AU33+AV33 -> 0 | AX33: =AY33+AZ33 -> 0 | AY33: =C33+G33+K33+O33+S33+W33+AA33+AE33+AI33+AM33+AQ33+AU33 -> 0 | AZ33: =D33+H33+L33+P33+T33+X33+AB33+AF33+AJ33+AN33+AR33+AV33 -> 0
... A53: PROJETO HUB | B53: =C53+D53 -> 0 | F53: =G53+H53 -> 0 | J53: =K53+L53 -> 0 | N53: =O53+P53 -> 0 | R53: =S53+T53 -> 0 | V53: =W53+X53 -> 0 | Z53: =AA53+AB53 -> 0 | AD53: =AE53+AF53 -> 0 | AH53: =AI53+AJ53 -> 0 | AL53: =AM53+AN53 -> 0 | AP53: =AQ53+AR53 -> 0 | AT53: =AU53+AV53 -> 0 | AX53: =AY53+AZ53 -> 0 | AY53: =C53+G53+K53+O53+S53+W53+AA53+AE53+AI53+AM53+AQ53+AU53 -> 0 | AZ53: =D53+H53+L53+P53+T53+X53+AB53+AF53+AJ53+AN53+AR53+AV53 -> 0
B54: =C54+D54 -> 0 | F54: =G54+H54 -> 0 | J54: =K54+L54 -> 0 | N54: =O54+P54 -> 0 | R54: =S54+T54 -> 0 | V54: =W54+X54 -> 0 | Z54: =AA54+AB54 -> 0 | AD54: =AE54+AF54 -> 0 | AH54: =AI54+AJ54 -> 0 | AL54: =AM54+AN54 -> 0 | AP54: =AQ54+AR54 -> 0 | AT54: =AU54+AV54 -> 0 | AX54: =AY54+AZ54 -> 0 | AY54: =C54+G54+K54+O54+S54+W54+AA54+AE54+AI54+AM54+AQ54+AU54 -> 0 | AZ54: =D54+H54+L54+P54+T54+X54+AB54+AF54+AJ54+AN54+AR54+AV54 -> 0
A55: TOTAL | B55: =SUM(B22:B54) -> 0 | C55: =SUM(C22:C54) -> 0 | D55: =SUM(D22:D54) -> 0 | F55: =SUM(F22:F54) -> 0 | G55: =SUM(G22:G54) -> 0 | H55: =SUM(H22:H54) -> 0 | J55: =SUM(J22:J54) -> 0 | K55: =SUM(K22:K54) -> 0 | L55: =SUM(L22:L54) -> 0 | N55: =SUM(N22:N54) -> 0 | O55: =SUM(O22:O54) -> 0 | P55: =SUM(P22:P54) -> 0 | R55: =SUM(R22:R54) -> 0 | S55: =SUM(S22:S54) -> 0 | T55: =SUM(T22:T54) -> 0 | V55: =SUM(V22:V54) -> 0 | W55: =SUM(W22:W54) -> 0 | X55: =SUM(X22:X54) -> 0 | Z55: =SUM(Z22:Z54) -> 0 | AA55: =SUM(AA22:AA54) -> 0 | AB55: =SUM(AB22:AB54) -> 0 | AD55: =SUM(AD22:AD54) -> 0 | AE55: =SUM(AE22:AE54) -> 0 | AF55: =SUM(AF22:AF54) -> 0 | AH55: =SUM(AH22:AH54) -> 0 | AI55: =SUM(AI22:AI54) -> 0 | AJ55: =SUM(AJ22:AJ54) -> 0 | AL55: =SUM(AL22:AL54) -> 0 | AM55: =SUM(AM22:AM54) -> 0 | AN55: =SUM(AN22:AN54) -> 0 | AP55: =SUM(AP22:AP54) -> 0 | AQ55: =SUM(AQ22:AQ54) -> 0 | AR55: =SUM(AR22:AR54) -> 0 | AT55: =SUM(AT22:AT54) -> 0 | AU55: =SUM(AU22:AU54) -> 0 | AV55: =SUM(AV22:AV54) -> 0 | AX55: =SUM(AX22:AX54) -> 0 | AY55: =SUM(AY22:AY54) -> 0 | AZ55: =SUM(AZ22:AZ54) -> 0
A57: RESUMO DA FOLHA | B57: =B20+B55 -> 0 | C57: =C20+C55 -> 0 | D57: =D20+D55 -> 0 | F57: =F20+F55 -> 0 | G57: =G20+G55 -> 0 | H57: =H20+H55 -> 0 | J57: =J20+J55 -> 0 | K57: =K20+K55 -> 0 | L57: =L20+L55 -> 0 | N57: =N20+N55 -> 0 | O57: =O20+O55 -> 0 | P57: =P20+P55 -> 0 | R57: =R20+R55 -> 0 | S57: =S20+S55 -> 0 | T57: =T20+T55 -> 0 | V57: =V20+V55 -> 0 | W57: =W20+W55 -> 0 | X57: =X20+X55 -> 0 | Z57: =Z20+Z55 -> 0 | AA57: =AA20+AA55 -> 0 | AB57: =AB20+AB55 -> 0 | AD57: =AD20+AD55 -> 0 | AE57: =AE20+AE55 -> 0 | AF57: =AF20+AF55 -> 0 | AH57: =AH20+AH55 -> 0 | AI57: =AI20+AI55 -> 0 | AJ57: =AJ20+AJ55 -> 0 | AL57: =AL20+AL55 -> 0 | AM57: =AM20+AM55 -> 0 | AN57: =AN20+AN55 -> 0 | AP57: =AP20+AP55 -> 0 | AQ57: =AQ20+AQ55 -> 0 | AR57: =AR20+AR55 -> 0 | AT57: =AT20+AT55 -> 0 | AU57: =AU20+AU55 -> 0 | AV57: =AV20+AV55 -> 0 | AX57: =AX20+AX55 -> 0 | AY57: =AY20+AY55 -> 0 | AZ57: =AZ20+AZ55 -> 0
A58: Participação | C58: =IF(B57=0,0,C57/B57) -> 0 | D58: =IF(B57=0,0,D57/B57) -> 0 | G58: =IF(F57=0,0,G57/F57) -> 0 | H58: =IF(F57=0,0,H57/F57) -> 0 | K58: =IF(J57=0,0,K57/J57) -> 0 | L58: =IF(J57=0,0,L57/J57) -> 0 | O58: =IF(N57=0,0,O57/N57) -> 0 | P58: =IF(N57=0,0,P57/N57) -> 0 | S58: =IF(R57=0,0,S57/R57) -> 0 | T58: =IF(R57=0,0,T57/R57) -> 0 | W58: =IF(V57=0,0,W57/V57) -> 0 | X58: =IF(V57=0,0,X57/V57) -> 0 | AA58: =IF(Z57=0,0,AA57/Z57) -> 0 | AB58: =IF(Z57=0,0,AB57/Z57) -> 0 | AE58: =IF(AD57=0,0,AE57/AD57) -> 0 | AF58: =IF(AD57=0,0,AF57/AD57) -> 0 | AI58: =IF(AH57=0,0,AI57/AH57) -> 0 | AJ58: =IF(AH57=0,0,AJ57/AH57) -> 0 | AM58: =IF(AL57=0,0,AM57/AL57) -> 0 | AN58: =IF(AL57=0,0,AN57/AL57) -> 0 | AQ58: =IF(AP57=0,0,AQ57/AP57) -> 0 | AR58: =IF(AP57=0,0,AR57/AP57) -> 0 | AU58: =IF(AT57=0,0,AU57/AT57) -> 0 | AV58: =IF(AT57=0,0,AV57/AT57) -> 0 | AY58: =IF(AX57=0,0,AY57/AX57) -> 0 | AZ58: =IF(AX57=0,0,AZ57/AX57) -> 0

Sheet Tarifas Bancárias
B2: DOC/TED Internet | C2: DOC/TED Pessoal | D2: Manut. Conta | E2: Manut. Crot | F2: Caixa Seguros | G2: Cartão de Crédito | H2: Seguro Residencial | I2: Deb. Cesta PJ | J2: Deb IOF | K2: Deb Juros | L2: Deb Avulso | M2: Lib talão | N2: Tar Excess | O2: Taxa Devol | P2: TR D CH | Q2: T D Din Ag | R2: Tar Saq Ag | S2: Tar SQ ATM | T2: Tar Bco24H | U2: seguradora | V2: Tar Doc In | W2: Tar Ren Car | X2: Tarifa Pix | Y2: Total
A4: 43466 | Y4: =SUM(B4:X4) -> 0
A5: 43467 | J5: 6.12 | K5: 20.9 | Y5: =SUM(B5:X5) -> 27.02
A6: 43468 | Y6: =SUM(B6:X6) -> 0
A7: 43469 | Y7: =SUM(B7:X7) -> 0
A8: 43470 | Y8: =SUM(B8:X8) -> 0
A9: 43471 | Y9: =SUM(B9:X9) -> 0
A10: 43472 | Y10: =SUM(B10:X10) -> 0
A11: 43473 | Y11: =SUM(B11:X11) -> 0
A12: 43474 | Y12: =SUM(B12:X12) -> 0
A13: 43475 | Y13: =SUM(B13:X13) -> 0
A14: 43476 | Y14: =SUM(B14:X14) -> 0
A15: 43477 | I15: 75 | Y15: =SUM(B15:X15) -> 75
A16: 43478 | Y16: =SUM(B16:X16) -> 0
A17: 43479 | Y17: =SUM(B17:X17) -> 0
A18: 43480 | X18: 0.07 | Y18: =SUM(B18:X18) -> 0.07
A19: 43481 | X19: =0.75+4 -> 4.75 | Y19: =SUM(B19:X19) -> 4.75
A20: 43482 | Y20: =SUM(B20:X20) -> 0
A21: 43483 | Y21: =SUM(B21:X21) -> 0
A22: 43484 | Y22: =SUM(B22:X22) -> 0
A23: 43485 | Y23: =SUM(B23:X23) -> 0
A24: 43486 | Y24: =SUM(B24:X24) -> 0
A25: 43487 | Y25: =SUM(B25:X25) -> 0
A26: 43488 | Y26: =SUM(B26:X26) -> 0
A27: 43489 | Y27: =SUM(B27:X27) -> 0
A28: 43490 | Y28: =SUM(B28:X28) -> 0
A29: 43491 | F29: 236.75 | X29: 1.84 | Y29: =SUM(B29:X29) -> 238.59
A30: 43492 | X30: =4+4.09 -> 8.09 | Y30: =SUM(B30:X30) -> 8.09
A31: 43493 | X31: 0.48 | Y31: =SUM(B31:X31) -> 0.48
A32: 43494 | X32: =130+8.5+6.23 -> 144.73 | Y32: =SUM(B32:X32) -> 144.73
A33: 43495 | X33: 4 | Y33: =SUM(B33:X33) -> 4
A34: 43496 | Y34: =SUM(B34:X34) -> 0
Y35: =SUM(B35:X35) -> 0
B36: =SUM(B3:B35) -> 0 | C36: =SUM(C3:C35) -> 0 | D36: =SUM(D3:D35) -> 0 | E36: =SUM(E3:E35) -> 0 | F36: =SUM(F3:F35) -> 236.75 | G36: =SUM(G3:G35) -> 0 | H36: =SUM(H3:H35) -> 0 | I36: =SUM(I3:I35) -> 75 | ... Y36: =SUM(Y3:Y35) -> 502.73
Y37: =SUM(B37:X37) -> 0
A38: 43497 | Y38: =SUM(B38:X38) -> 0
A39: 43498 | J39: 48.37 | K39: 245.87 | Y39: =SUM(B39:X39) -> 294.24
A40: 43499 | X40: 1.51 | Y40: =SUM(B40:X40) -> 1.51
A41: 43500 | X41: 4 | Y41: =SUM(B41:X41) -> 4
A42: 43501 | Y42: =SUM(B42:X42) -> 0
...
